....EE
======================================================================
ERROR: test_can_save_a_POST_request (lists.tests.NewListTest)
----------------------------------------------------------------------
Traceback (most recent call last):
  File "/home/onejay/.local/lib/python3.8/site-packages/django/db/backends/utils.py", line 64, in execute
    return self.cursor.execute(sql, params)
  File "/home/onejay/.local/lib/python3.8/site-packages/django/db/backends/sqlite3/base.py", line 328, in execute
    return Database.Cursor.execute(self, query, params)
sqlite3.IntegrityError: NOT NULL constraint failed: lists_item.list_id

The above exception was the direct cause of the following exception:

Traceback (most recent call last):
  File "/home/onejay/PythonTTD/superlist/lists/tests.py", line 14, in test_can_save_a_POST_request
    response = self.client.post('/lists/new', data={'item_text':'A new list item'})
  File "/home/onejay/.local/lib/python3.8/site-packages/django/test/client.py", line 546, in post
    response = super(Client, self).post(path, data=data,
  File "/home/onejay/.local/lib/python3.8/site-packages/django/test/client.py", line 349, in post
    return self.generic('POST', path, post_data, content_type,
  File "/home/onejay/.local/lib/python3.8/site-packages/django/test/client.py", line 416, in generic
    return self.request(**r)
  File "/home/onejay/.local/lib/python3.8/site-packages/django/test/client.py", line 501, in request
    six.reraise(*exc_info)
  File "/home/onejay/.local/lib/python3.8/site-packages/django/utils/six.py", line 686, in reraise
    raise value
  File "/home/onejay/.local/lib/python3.8/site-packages/django/core/handlers/exception.py", line 41, in inner
    response = get_response(request)
  File "/home/onejay/.local/lib/python3.8/site-packages/django/core/handlers/base.py", line 249, in _legacy_get_response
    response = self._get_response(request)
  File "/home/onejay/.local/lib/python3.8/site-packages/django/core/handlers/base.py", line 187, in _get_response
    response = self.process_exception_by_middleware(e, request)
  File "/home/onejay/.local/lib/python3.8/site-packages/django/core/handlers/base.py", line 185, in _get_response
    response = wrapped_callback(request, *callback_args, **callback_kwargs)
  File "/home/onejay/PythonTTD/superlist/lists/views.py", line 9, in new_list
    Item.objects.create(text=request.POST['item_text'])
  File "/home/onejay/.local/lib/python3.8/site-packages/django/db/models/manager.py", line 85, in manager_method
    return getattr(self.get_queryset(), name)(*args, **kwargs)
  File "/home/onejay/.local/lib/python3.8/site-packages/django/db/models/query.py", line 394, in create
    obj.save(force_insert=True, using=self.db)
  File "/home/onejay/.local/lib/python3.8/site-packages/django/db/models/base.py", line 807, in save
    self.save_base(using=using, force_insert=force_insert,
  File "/home/onejay/.local/lib/python3.8/site-packages/django/db/models/base.py", line 838, in save_base
    updated = self._save_table(raw, cls, force_insert, force_update, using, update_fields)
  File "/home/onejay/.local/lib/python3.8/site-packages/django/db/models/base.py", line 924, in _save_table
    result = self._do_insert(cls._base_manager, using, fields, update_pk, raw)
  File "/home/onejay/.local/lib/python3.8/site-packages/django/db/models/base.py", line 962, in _do_insert
    return manager._insert([self], fields=fields, return_id=update_pk,
  File "/home/onejay/.local/lib/python3.8/site-packages/django/db/models/manager.py", line 85, in manager_method
    return getattr(self.get_queryset(), name)(*args, **kwargs)
  File "/home/onejay/.local/lib/python3.8/site-packages/django/db/models/query.py", line 1079, in _insert
    return query.get_compiler(using=using).execute_sql(return_id)
  File "/home/onejay/.local/lib/python3.8/site-packages/django/db/models/sql/compiler.py", line 1112, in execute_sql
    cursor.execute(sql, params)
  File "/home/onejay/.local/lib/python3.8/site-packages/django/db/backends/utils.py", line 64, in execute
    return self.cursor.execute(sql, params)
  File "/home/onejay/.local/lib/python3.8/site-packages/django/db/utils.py", line 94, in __exit__
    six.reraise(dj_exc_type, dj_exc_value, traceback)
  File "/home/onejay/.local/lib/python3.8/site-packages/django/utils/six.py", line 685, in reraise
    raise value.with_traceback(tb)
  File "/home/onejay/.local/lib/python3.8/site-packages/django/db/backends/utils.py", line 64, in execute
    return self.cursor.execute(sql, params)
  File "/home/onejay/.local/lib/python3.8/site-packages/django/db/backends/sqlite3/base.py", line 328, in execute
    return Database.Cursor.execute(self, query, params)
django.db.utils.IntegrityError: NOT NULL constraint failed: lists_item.list_id

======================================================================
ERROR: test_redirects_after_POST (lists.tests.NewListTest)
----------------------------------------------------------------------
Traceback (most recent call last):
  File "/home/onejay/.local/lib/python3.8/site-packages/django/db/backends/utils.py", line 64, in execute
    return self.cursor.execute(sql, params)
  File "/home/onejay/.local/lib/python3.8/site-packages/django/db/backends/sqlite3/base.py", line 328, in execute
    return Database.Cursor.execute(self, query, params)
sqlite3.IntegrityError: NOT NULL constraint failed: lists_item.list_id

The above exception was the direct cause of the following exception:

Traceback (most recent call last):
  File "/home/onejay/PythonTTD/superlist/lists/tests.py", line 28, in test_redirects_after_POST
    response = self.client.post('/lists/new', data={'item_text':'A new list item'})
  File "/home/onejay/.local/lib/python3.8/site-packages/django/test/client.py", line 546, in post
    response = super(Client, self).post(path, data=data,
  File "/home/onejay/.local/lib/python3.8/site-packages/django/test/client.py", line 349, in post
    return self.generic('POST', path, post_data, content_type,
  File "/home/onejay/.local/lib/python3.8/site-packages/django/test/client.py", line 416, in generic
    return self.request(**r)
  File "/home/onejay/.local/lib/python3.8/site-packages/django/test/client.py", line 501, in request
    six.reraise(*exc_info)
  File "/home/onejay/.local/lib/python3.8/site-packages/django/utils/six.py", line 686, in reraise
    raise value
  File "/home/onejay/.local/lib/python3.8/site-packages/django/core/handlers/exception.py", line 41, in inner
    response = get_response(request)
  File "/home/onejay/.local/lib/python3.8/site-packages/django/core/handlers/base.py", line 249, in _legacy_get_response
    response = self._get_response(request)
  File "/home/onejay/.local/lib/python3.8/site-packages/django/core/handlers/base.py", line 187, in _get_response
    response = self.process_exception_by_middleware(e, request)
  File "/home/onejay/.local/lib/python3.8/site-packages/django/core/handlers/base.py", line 185, in _get_response
    response = wrapped_callback(request, *callback_args, **callback_kwargs)
  File "/home/onejay/PythonTTD/superlist/lists/views.py", line 9, in new_list
    Item.objects.create(text=request.POST['item_text'])
  File "/home/onejay/.local/lib/python3.8/site-packages/django/db/models/manager.py", line 85, in manager_method
    return getattr(self.get_queryset(), name)(*args, **kwargs)
  File "/home/onejay/.local/lib/python3.8/site-packages/django/db/models/query.py", line 394, in create
    obj.save(force_insert=True, using=self.db)
  File "/home/onejay/.local/lib/python3.8/site-packages/django/db/models/base.py", line 807, in save
    self.save_base(using=using, force_insert=force_insert,
  File "/home/onejay/.local/lib/python3.8/site-packages/django/db/models/base.py", line 838, in save_base
    updated = self._save_table(raw, cls, force_insert, force_update, using, update_fields)
  File "/home/onejay/.local/lib/python3.8/site-packages/django/db/models/base.py", line 924, in _save_table
    result = self._do_insert(cls._base_manager, using, fields, update_pk, raw)
  File "/home/onejay/.local/lib/python3.8/site-packages/django/db/models/base.py", line 962, in _do_insert
    return manager._insert([self], fields=fields, return_id=update_pk,
  File "/home/onejay/.local/lib/python3.8/site-packages/django/db/models/manager.py", line 85, in manager_method
    return getattr(self.get_queryset(), name)(*args, **kwargs)
  File "/home/onejay/.local/lib/python3.8/site-packages/django/db/models/query.py", line 1079, in _insert
    return query.get_compiler(using=using).execute_sql(return_id)
  File "/home/onejay/.local/lib/python3.8/site-packages/django/db/models/sql/compiler.py", line 1112, in execute_sql
    cursor.execute(sql, params)
  File "/home/onejay/.local/lib/python3.8/site-packages/django/db/backends/utils.py", line 64, in execute
    return self.cursor.execute(sql, params)
  File "/home/onejay/.local/lib/python3.8/site-packages/django/db/utils.py", line 94, in __exit__
    six.reraise(dj_exc_type, dj_exc_value, traceback)
  File "/home/onejay/.local/lib/python3.8/site-packages/django/utils/six.py", line 685, in reraise
    raise value.with_traceback(tb)
  File "/home/onejay/.local/lib/python3.8/site-packages/django/db/backends/utils.py", line 64, in execute
    return self.cursor.execute(sql, params)
  File "/home/onejay/.local/lib/python3.8/site-packages/django/db/backends/sqlite3/base.py", line 328, in execute
    return Database.Cursor.execute(self, query, params)
django.db.utils.IntegrityError: NOT NULL constraint failed: lists_item.list_id

----------------------------------------------------------------------
Ran 6 tests in 0.036s

FAILED (errors=2)
